<sdf version='1.6'>
  <world name='default'>
    <light name='sun' type='directional'>
      <cast_shadows>1</cast_shadows>
      <pose frame=''>0 0 10 0 -0 0</pose>
      <diffuse>0.8 0.8 0.8 1</diffuse>
      <specular>0.2 0.2 0.2 1</specular>
      <attenuation>
        <range>1000</range>
        <constant>0.9</constant>
        <linear>0.01</linear>
        <quadratic>0.001</quadratic>
      </attenuation>
      <direction>-0.5 0.1 -0.9</direction>
    </light>
    <model name='ground_plane'>
      <static>1</static>
      <link name='link'>
        <collision name='collision'>
          <geometry>
            <plane>
              <normal>0 0 1</normal>
              <size>100 100</size>
            </plane>
          </geometry>
          <surface>
            <contact>
              <collide_bitmask>65535</collide_bitmask>
              <ode/>
            </contact>
            <friction>
              <ode>
                <mu>100</mu>
                <mu2>50</mu2>
              </ode>
              <torsional>
                <ode/>
              </torsional>
            </friction>
            <bounce/>
          </surface>
          <max_contacts>10</max_contacts>
        </collision>
        <visual name='visual'>
          <cast_shadows>0</cast_shadows>
          <geometry>
            <plane>
              <normal>0 0 1</normal>
              <size>100 100</size>
            </plane>
          </geometry>
          <material>
            <script>
              <uri>file://media/materials/scripts/gazebo.material</uri>
              <name>Gazebo/Grey</name>
            </script>
          </material>
        </visual>
        <self_collide>0</self_collide>
        <enable_wind>0</enable_wind>
        <kinematic>0</kinematic>
      </link>
    </model>
    <gravity>0 0 -9.8</gravity>
    <magnetic_field>6e-06 2.3e-05 -4.2e-05</magnetic_field>
    <atmosphere type='adiabatic'/>
    <physics name='default_physics' default='0' type='ode'>
      <max_step_size>0.001</max_step_size>
      <real_time_factor>1</real_time_factor>
      <real_time_update_rate>1000</real_time_update_rate>
    </physics>
    <scene>
      <ambient>0.4 0.4 0.4 1</ambient>
      <background>0.7 0.7 0.7 1</background>
      <shadows>1</shadows>
    </scene>
    <audio>
      <device>default</device>
    </audio>
    <wind/>
    <spherical_coordinates>
      <surface_model>EARTH_WGS84</surface_model>
      <latitude_deg>0</latitude_deg>
      <longitude_deg>0</longitude_deg>
      <elevation>0</elevation>
      <heading_deg>0</heading_deg>
    </spherical_coordinates>
    <model name='mira'>
      <link name='base_link'>
        <pose frame=''>0 0 0 0 -0 0</pose>
        <inertial>
          <pose frame=''>0 0 0 0 -0 0</pose>
          <mass>0.18</mass>
          <inertia>
            <ixx>0.0002835</ixx>
            <ixy>0</ixy>
            <ixz>0</ixz>
            <iyy>0.0002835</iyy>
            <iyz>0</iyz>
            <izz>0.000324</izz>
          </inertia>
        </inertial>
        <collision name='base_link_collision'>
          <pose frame=''>0 0 0 0 -0 0</pose>
          <geometry>
            <cylinder>
              <length>0.09</length>
              <radius>0.06</radius>
            </cylinder>
          </geometry>
          <max_contacts>10</max_contacts>
          <surface>
            <contact>
              <ode/>
            </contact>
            <bounce/>
            <friction>
              <torsional>
                <ode/>
              </torsional>
              <ode/>
            </friction>
          </surface>
        </collision>
        <visual name='base_link_visual'>
          <pose frame=''>0 0 0 0 -0 0</pose>
          <geometry>
            <mesh>
              <scale>1 1 1</scale>
              <uri>/home/min/catkin_ws/src/urdf_exam/meshes/mira_body_v3.dae</uri>
            </mesh>
          </geometry>
        </visual>
        <self_collide>0</self_collide>
        <enable_wind>0</enable_wind>
        <kinematic>0</kinematic>
      </link>
      <link name='roll_M1_link'>
        <pose frame=''>0.0023 0 -0.0005 0 -0 0</pose>
        <inertial>
          <pose frame=''>0 0 0 0 -0 0</pose>
          <mass>0.001</mass>
          <inertia>
            <ixx>2.70833e-08</ixx>
            <ixy>0</ixy>
            <ixz>0</ixz>
            <iyy>2.70833e-08</iyy>
            <iyz>0</iyz>
            <izz>5e-08</izz>
          </inertia>
        </inertial>
        <visual name='roll_M1_link_visual'>
          <pose frame=''>0 0 0 0 -0 0</pose>
          <geometry>
            <cylinder>
              <length>0.003</length>
              <radius>0.005</radius>
            </cylinder>
          </geometry>
          <material>
            <script>
              <name>Gazebo/Red</name>
              <uri>file://media/materials/scripts/gazebo.material</uri>
            </script>
          </material>
        </visual>
        <gravity>1</gravity>
        <velocity_decay/>
        <self_collide>0</self_collide>
        <enable_wind>0</enable_wind>
        <kinematic>0</kinematic>
      </link>
      <joint name='roll_joint' type='revolute'>
        <child>roll_M1_link</child>
        <parent>base_link</parent>
        <axis>
          <xyz>1 0 0</xyz>
          <limit>
            <lower>-0.2</lower>
            <upper>0.2</upper>
            <effort>0.1</effort>
            <velocity>0.005</velocity>
          </limit>
          <dynamics>
            <spring_reference>0</spring_reference>
            <spring_stiffness>0</spring_stiffness>
          </dynamics>
          <use_parent_model_frame>1</use_parent_model_frame>
        </axis>
      </joint>
      <link name='pitch_M2_link'>
        <pose frame=''>0.0023 0 -0.0005 3.14159 -1.57079 3.14159</pose>
        <inertial>
          <pose frame=''>0 0 0 0 -0 0</pose>
          <mass>0.001</mass>
          <inertia>
            <ixx>2.70833e-08</ixx>
            <ixy>0</ixy>
            <ixz>0</ixz>
            <iyy>2.70833e-08</iyy>
            <iyz>0</iyz>
            <izz>5e-08</izz>
          </inertia>
        </inertial>
        <visual name='pitch_M2_link_visual'>
          <pose frame=''>0 0 0 0 -0 0</pose>
          <geometry>
            <cylinder>
              <length>0.003</length>
              <radius>0.005</radius>
            </cylinder>
          </geometry>
          <material>
            <script>
              <name>Gazebo/Green</name>
              <uri>file://media/materials/scripts/gazebo.material</uri>
            </script>
          </material>
        </visual>
        <gravity>1</gravity>
        <velocity_decay/>
        <self_collide>0</self_collide>
        <enable_wind>0</enable_wind>
        <kinematic>0</kinematic>
      </link>
      <joint name='pitch_joint' type='revolute'>
        <child>pitch_M2_link</child>
        <parent>roll_M1_link</parent>
        <axis>
          <xyz>0 1 0</xyz>
          <limit>
            <lower>0</lower>
            <upper>0.44</upper>
            <effort>0.1</effort>
            <velocity>0.005</velocity>
          </limit>
          <dynamics>
            <spring_reference>0</spring_reference>
            <spring_stiffness>0</spring_stiffness>
          </dynamics>
          <use_parent_model_frame>1</use_parent_model_frame>
        </axis>
      </joint>
      <link name='yaw_M3_link'>
        <pose frame=''>0.0023 0 0.0095 0 -0 0</pose>
        <inertial>
          <pose frame=''>0 0.004957 0.000739 0 -0 0</pose>
          <mass>0.023</mass>
          <inertia>
            <ixx>3.2277e-05</ixx>
            <ixy>0</ixy>
            <ixz>0</ixz>
            <iyy>2.65337e-05</iyy>
            <iyz>-8.84739e-07</iyz>
            <izz>4.21818e-05</izz>
          </inertia>
        </inertial>
        <collision name='yaw_M3_link_fixed_joint_lump__head_link_collision'>
          <pose frame=''>0 0 0.015 0 -0 0</pose>
          <geometry>
            <sphere>
              <radius>0.06</radius>
            </sphere>
          </geometry>
          <surface>
            <contact>
              <ode>
                <kp>100000</kp>
                <kd>100000</kd>
              </ode>
            </contact>
            <friction>
              <ode>
                <mu>10</mu>
                <mu2>10</mu2>
              </ode>
              <torsional>
                <ode/>
              </torsional>
            </friction>
            <bounce/>
          </surface>
          <max_contacts>10</max_contacts>
        </collision>
        <visual name='yaw_M3_link_visual'>
          <pose frame=''>0 0 0 0 -0 0</pose>
          <geometry>
            <cylinder>
              <length>0.005</length>
              <radius>0.01</radius>
            </cylinder>
          </geometry>
          <material>
            <script>
              <name>Gazebo/Green</name>
              <uri>file://media/materials/scripts/gazebo.material</uri>
            </script>
          </material>
        </visual>
        <visual name='yaw_M3_link_fixed_joint_lump__head_link_visual_1'>
          <pose frame=''>0 0 0 0 -0 0</pose>
          <geometry>
            <mesh>
              <scale>1 1 1</scale>
              <uri>/home/min/catkin_ws/src/urdf_exam/meshes/mira_head_v5.dae</uri>
            </mesh>
          </geometry>
          <material>
            <script>
              <name>Gazebo/White</name>
              <uri>file://media/materials/scripts/gazebo.material</uri>
            </script>
          </material>
        </visual>
        <visual name='yaw_M3_link_fixed_joint_lump__camera_link_visual_2'>
          <pose frame=''>0 0.057 0.0255 0 -0 0</pose>
          <geometry>
            <box>
              <size>0.0005 0.0005 0.0005</size>
            </box>
          </geometry>
          <material>
            <script>
              <uri>__default__</uri>
              <name>__default__</name>
            </script>
          </material>
        </visual>
        <visual name='yaw_M3_link_fixed_joint_lump__left_eye_link_visual_3'>
          <pose frame=''>0.0095 0.057 0.0085 -1.5708 0 0</pose>
          <geometry>
            <mesh>
              <scale>1 1 1</scale>
              <uri>/home/min/catkin_ws/src/urdf_exam/meshes/mira_eye_v4.dae</uri>
            </mesh>
          </geometry>
          <material>
            <script>
              <name>Gazebo/White</name>
              <uri>file://media/materials/scripts/gazebo.material</uri>
            </script>
          </material>
        </visual>
        <visual name='yaw_M3_link_fixed_joint_lump__right_eye_link_visual_4'>
          <pose frame=''>-0.0095 0.057 0.0085 -1.5708 0 0</pose>
          <geometry>
            <mesh>
              <scale>1 1 1</scale>
              <uri>/home/min/catkin_ws/src/urdf_exam/meshes/mira_eye_v4.dae</uri>
            </mesh>
          </geometry>
          <material>
            <script>
              <name>Gazebo/White</name>
              <uri>file://media/materials/scripts/gazebo.material</uri>
            </script>
          </material>
        </visual>
        <velocity_decay/>
        <velocity_decay/>
        <velocity_decay/>
        <sensor name='camera1' type='camera'>
          <update_rate>15</update_rate>
          <camera name='head'>
            <pose frame=''>0 0 0 0 -0 1.57</pose>
            <horizontal_fov>1.39626</horizontal_fov>
            <image>
              <width>400</width>
              <height>400</height>
              <format>R8G8B8</format>
            </image>
            <clip>
              <near>0.01</near>
              <far>100</far>
            </clip>
            <noise>
              <type>gaussian</type>
              <stddev>0.007</stddev>
            </noise>
          </camera>
          <plugin name='camera_controller' filename='libgazebo_ros_camera.so'>
            <alwaysOn>1</alwaysOn>
            <updateRate>0.0</updateRate>
            <cameraName>mira/camera1</cameraName>
            <imageTopicName>image_raw</imageTopicName>
            <cameraInfoTopicName>camera_info</cameraInfoTopicName>
            <frameName>camera_link</frameName>
            <hackBaseline>0.07</hackBaseline>
            <distortionK1>0.0</distortionK1>
            <distortionK2>0.0</distortionK2>
            <distortionK3>0.0</distortionK3>
            <distortionT1>0.0</distortionT1>
            <distortionT2>0.0</distortionT2>
            <robotNamespace>/</robotNamespace>
          </plugin>
          <pose frame=''>0 0.057 0.0255 0 -0 0</pose>
        </sensor>
        <velocity_decay/>
        <gravity>1</gravity>
        <velocity_decay/>
        <self_collide>0</self_collide>
        <enable_wind>0</enable_wind>
        <kinematic>0</kinematic>
      </link>
      <joint name='yaw_joint' type='revolute'>
        <child>yaw_M3_link</child>
        <parent>pitch_M2_link</parent>
        <axis>
          <xyz>0 0 1</xyz>
          <limit>
            <lower>-1e+16</lower>
            <upper>1e+16</upper>
          </limit>
          <dynamics>
            <spring_reference>0</spring_reference>
            <spring_stiffness>0</spring_stiffness>
          </dynamics>
          <use_parent_model_frame>1</use_parent_model_frame>
        </axis>
      </joint>
      <static>0</static>
      <plugin name='gazebo_ros_control' filename='libgazebo_ros_control.so'>
        <robotNamespace>/mira</robotNamespace>
      </plugin>
      <pose frame=''>0 0 0.045 0 -0 0</pose>
    </model>
    <model name='unit_sphere'>
      <pose frame=''>-3.87553 2.47393 0.5 0 -0 0</pose>
      <link name='link'>
        <inertial>
          <mass>1</mass>
          <inertia>
            <ixx>0.1</ixx>
            <ixy>0</ixy>
            <ixz>0</ixz>
            <iyy>0.1</iyy>
            <iyz>0</iyz>
            <izz>0.1</izz>
          </inertia>
        </inertial>
        <collision name='collision'>
          <geometry>
            <sphere>
              <radius>0.500001</radius>
            </sphere>
          </geometry>
          <max_contacts>10</max_contacts>
          <surface>
            <contact>
              <ode/>
            </contact>
            <bounce/>
            <friction>
              <torsional>
                <ode/>
              </torsional>
              <ode/>
            </friction>
          </surface>
        </collision>
        <visual name='visual'>
          <geometry>
            <sphere>
              <radius>0.500001</radius>
            </sphere>
          </geometry>
          <material>
            <script>
              <name>Gazebo/Grey</name>
              <uri>file://media/materials/scripts/gazebo.material</uri>
            </script>
          </material>
        </visual>
        <self_collide>0</self_collide>
        <enable_wind>0</enable_wind>
        <kinematic>0</kinematic>
      </link>
    </model>
    <model name='unit_cylinder'>
      <pose frame=''>2.3042 0.990676 0.5 0 -0 0</pose>
      <link name='link'>
        <inertial>
          <mass>1</mass>
          <inertia>
            <ixx>0.145833</ixx>
            <ixy>0</ixy>
            <ixz>0</ixz>
            <iyy>0.145833</iyy>
            <iyz>0</iyz>
            <izz>0.125</izz>
          </inertia>
        </inertial>
        <collision name='collision'>
          <geometry>
            <cylinder>
              <radius>0.5</radius>
              <length>1</length>
            </cylinder>
          </geometry>
          <max_contacts>10</max_contacts>
          <surface>
            <contact>
              <ode/>
            </contact>
            <bounce/>
            <friction>
              <torsional>
                <ode/>
              </torsional>
              <ode/>
            </friction>
          </surface>
        </collision>
        <visual name='visual'>
          <geometry>
            <cylinder>
              <radius>0.5</radius>
              <length>1</length>
            </cylinder>
          </geometry>
          <material>
            <script>
              <name>Gazebo/Grey</name>
              <uri>file://media/materials/scripts/gazebo.material</uri>
            </script>
          </material>
        </visual>
        <self_collide>0</self_collide>
        <enable_wind>0</enable_wind>
        <kinematic>0</kinematic>
      </link>
    </model>
    <state world_name='default'>
      <sim_time>34 398000000</sim_time>
      <real_time>37 76990016</real_time>
      <wall_time>1628048946 603038820</wall_time>
      <iterations>34398</iterations>
      <model name='ground_plane'>
        <pose frame=''>0 0 0 0 -0 0</pose>
        <scale>1 1 1</scale>
        <link name='link'>
          <pose frame=''>0 0 0 0 -0 0</pose>
          <velocity>0 0 0 0 -0 0</velocity>
          <acceleration>0 0 0 0 -0 0</acceleration>
          <wrench>0 0 0 0 -0 0</wrench>
        </link>
      </model>
      <model name='mira'>
        <pose frame=''>-0.002133 -1.4e-05 0.045 0 0 -1.56668</pose>
        <scale>1 1 1</scale>
        <link name='base_link'>
          <pose frame=''>-0.002133 -1.4e-05 0.045 0 0 -1.56668</pose>
          <velocity>-0.003257 -0.000303 0.005529 0.006731 -0.072374 0</velocity>
          <acceleration>-5.97978 -0.601925 11.062 0.91969 -1.35489 0.863032</acceleration>
          <wrench>-1.07636 -0.108346 1.99115 0 -0 0</wrench>
        </link>
        <link name='pitch_M2_link'>
          <pose frame=''>-0.002124 -0.002314 0.044498 -1.56858 -1.56916 0.001896</pose>
          <velocity>-0.002594 -0.000263 0.004976 0.011641 -0.106909 2.3e-05</velocity>
          <acceleration>-5.2067 -0.550643 9.9896 0.816672 1.20556 -2.74931</acceleration>
          <wrench>-0.005207 -0.000551 0.00999 0 -0 0</wrench>
        </link>
        <link name='roll_M1_link'>
          <pose frame=''>-0.002123 -0.002314 0.044501 -0.001634 -0 -1.56668</pose>
          <velocity>-0.003668 -0.000326 0.005915 0.006796 -0.105841 3.3e-05</velocity>
          <acceleration>-6.41697 -0.628994 11.8084 -2.71619 0.673246 -2.12358</acceleration>
          <wrench>-0.006417 -0.000629 0.011808 0 -0 0</wrench>
        </link>
        <link name='yaw_M3_link'>
          <pose frame=''>-0.002111 -0.002314 0.054494 -0.001559 1e-05 -1.56671</pose>
          <velocity>0.000921 2e-05 0.003617 0.00211 -0.01369 0.00041</velocity>
          <acceleration>-0.402702 -0.142728 7.04744 -1.97855 1.44085 3.04858</acceleration>
          <wrench>-0.009262 -0.003283 0.162091 0 -0 0</wrench>
        </link>
      </model>
      <model name='unit_cylinder'>
        <pose frame=''>2.3042 0.990678 0.499993 -3e-06 -3e-06 0</pose>
        <scale>1 1 1</scale>
        <link name='link'>
          <pose frame=''>2.3042 0.990678 0.499993 -3e-06 -3e-06 0</pose>
          <velocity>0 0 0 0 -0 0</velocity>
          <acceleration>0 0 -9.8 0 -0 0</acceleration>
          <wrench>0 0 -9.8 0 -0 0</wrench>
        </link>
      </model>
      <model name='unit_sphere'>
        <pose frame=''>1.65773 0.556081 0.192857 0 -0 0</pose>
        <scale>0.385713 0.385713 0.385713</scale>
        <link name='link'>
          <pose frame=''>1.65773 0.556081 0.192857 0 -0 0</pose>
          <velocity>0 0 0 0 -0 0</velocity>
          <acceleration>0 0 0 0 -0 0</acceleration>
          <wrench>0 0 0 0 -0 0</wrench>
        </link>
      </model>
      <light name='sun'>
        <pose frame=''>0 0 10 0 -0 0</pose>
      </light>
    </state>
    <gui fullscreen='0'>
      <camera name='user_camera'>
        <pose frame=''>3.43088 -1.2187 1.08387 0 0.275643 2.35619</pose>
        <view_controller>orbit</view_controller>
        <projection_type>perspective</projection_type>
      </camera>
    </gui>
  </world>
</sdf>
